<?xml version="1.0" ?>
<robot name="errandbot">

  <material name="black">
      <color rgba="0.0 0.0 0.0 1.0"/>
  </material>

  <material name="dark">
    <color rgba="0.3 0.3 0.3 1.0"/>
  </material>

  <material name="light_black">
    <color rgba="0.4 0.4 0.4 1.0"/>
  </material>

  <material name="blue">
    <color rgba="0.0 0.0 0.8 1.0"/>
  </material>

  <material name="green">
    <color rgba="0.0 0.8 0.0 1.0"/>
  </material>

  <material name="grey">
    <color rgba="0.5 0.5 0.5 1.0"/>
  </material>

  <material name="orange">
    <color rgba="1.0 0.4235 0.0392 1.0"/>
  </material>

  <material name="brown">
    <color rgba="0.8706 0.8118 0.7647 1.0"/>
  </material>

  <material name="red">
    <color rgba="0.8 0.0 0.0 1.0"/>
  </material>

  <material name="white">
    <color rgba="1.0 1.0 1.0 1.0"/>
  </material>

  <link name="base_footprint"/>

  <joint name="base_joint" type="fixed">
    <parent link="base_footprint"/>
    <child link="base_link" />
    <origin xyz="0 0 0.075" rpy="0 0 0"/>
  </joint>

  <link name="base_link">
    <visual>
      <origin xyz="0 0 0.0875" rpy="0 0 0"/>
      <geometry>
        <box size="0.5 0.4 0.175" />
      </geometry>
      <material name="light_black"/>
    </visual>

    <collision>
      <origin xyz="0 0 0.0875" rpy="0 0 0"/>
      <geometry>
        <box size="0.5 0.4 0.175"/>
      </geometry>
    </collision>

    <inertial>
      <origin xyz="0 0 0.0875" rpy="0 0 0"/>
      <mass value="30.0"/>
      <inertia ixx="0.4765625" ixy="0" ixz="0"
               iyy="0.7015625" iyz="0"
               izz="1.025" />
    </inertial>
  </link>

  <joint name="wheel_left_joint" type="continuous">
    <parent link="base_link"/>
    <child link="wheel_left_link"/>
    <origin xyz="0 0.225 0" rpy="0 0 0"/>
    <axis xyz="0 1 0"/>
  </joint>

  <link name="wheel_left_link">
    <visual>
      <origin xyz="0 0 0" rpy="1.57 0 0"/>
      <geometry>
        <cylinder radius="0.075" length="0.05" />
      </geometry>
      <material name="dark"/>
    </visual>

    <collision>
      <origin xyz="0 0 0" rpy="0 0 0"/>
      <geometry>
        <sphere radius="0.075" />
      </geometry>
    </collision>

    <inertial>
      <origin xyz="0 0 0"/>
      <mass value="2.0" />
      <inertia ixx="3.2291666e-03" ixy="0" ixz="0"
               iyy="3.2291666e-03" iyz="0"
               izz="5.625e-03" />
    </inertial>
  </link>

  <joint name="wheel_right_joint" type="continuous">
    <parent link="base_link"/>
    <child link="wheel_right_link"/>
    <origin xyz="0.0 -0.225 0.0" rpy="0 0 0"/>
    <axis xyz="0 1 0"/>
  </joint>

  <link name="wheel_right_link">
    <visual>
      <origin xyz="0 0 0" rpy="1.57 0 0"/>
      <geometry>
        <cylinder radius="0.075" length="0.05" />
      </geometry>
      <material name="dark"/>
    </visual>

    <collision>
      <origin xyz="0 0 0" rpy="0 0 0"/>
      <geometry>
        <sphere radius="0.075" />
      </geometry>
    </collision>

    <inertial>
      <origin xyz="0 0 0" rpy="1.57 0 0"/>
      <mass value="2.0" />
      <inertia ixx="3.2291666e-03" ixy="0" ixz="0"
               iyy="3.2291666e-03" iyz="0"
               izz="5.625e-03" />
      </inertial>
  </link>

  <joint name="caster_back_right_joint" type="fixed">
    <parent link="base_link"/>
    <child link="caster_back_right_link"/>
    <origin xyz="-0.175 -0.175 -0.0375" rpy="0 0 0"/>
  </joint>

  <link name="caster_back_right_link">
    <visual>
      <origin xyz="0 0 0" rpy="0 0 0"/>
      <geometry>
        <sphere radius="0.0375" />
      </geometry>
      <material name="dark"/>
    </visual>

    <collision>
      <origin xyz="0 0 0" rpy="0 0 0"/>
      <geometry>
        <sphere radius="0.0375" />
      </geometry>
    </collision>

    <inertial>
      <origin xyz="0 0 0" />
      <mass value="1.5" />
      <inertia ixx="8.4375e-04" ixy="0.0" ixz="0.0"
               iyy="8.4375e-04" iyz="0.0"
               izz="8.4375e-04" />
    </inertial>
  </link>

  <joint name="caster_back_left_joint" type="fixed">
    <parent link="base_link"/>
    <child link="caster_back_left_link"/>
    <origin xyz="-0.175 0.175 -0.0375" rpy="0 0 0"/>
  </joint>

  <link name="caster_back_left_link">
    <visual>
      <origin xyz="0 0 0" rpy="0 0 0"/>
      <geometry>
        <sphere radius="0.0375" />
      </geometry>
      <material name="dark"/>
    </visual>

    <collision>
      <origin xyz="0 0 0" rpy="0 0 0"/>
      <geometry>
        <sphere radius="0.0375" />
      </geometry>
    </collision>

    <inertial>
      <origin xyz="0 0 0" />
      <mass value="1.5" />
      <inertia ixx="8.4375e-04" ixy="0.0" ixz="0.0"
               iyy="8.4375e-04" iyz="0.0"
               izz="8.4375e-04" />
    </inertial>
  </link>

  <joint name="caster_front_right_joint" type="fixed">
    <parent link="base_link"/>
    <child link="caster_front_right_link"/>
    <origin xyz="0.175 -0.175 -0.0375" rpy="0 0 0"/>
  </joint>

  <link name="caster_front_right_link">
    <visual>
      <origin xyz="0 0 0" rpy="0 0 0"/>
      <geometry>
        <sphere radius="0.0375" />
      </geometry>
      <material name="dark"/>
    </visual>

    <collision>
      <origin xyz="0 0 0" rpy="0 0 0"/>
      <geometry>
        <sphere radius="0.0375" />
      </geometry>
    </collision>

    <inertial>
      <origin xyz="0 0 0" />
      <mass value="1.5" />
      <inertia ixx="8.4375e-04" ixy="0.0" ixz="0.0"
               iyy="8.4375e-04" iyz="0.0"
               izz="8.4375e-04" />
    </inertial>
  </link>

  <joint name="caster_front_left_joint" type="fixed">
    <parent link="base_link"/>
    <child link="caster_front_left_link"/>
    <origin xyz="0.175 0.175 -0.0375" rpy="0 0 0"/>
  </joint>

  <link name="caster_front_left_link">
    <visual>
      <origin xyz="0 0 0" rpy="0 0 0"/>
      <geometry>
        <sphere radius="0.0375" />
      </geometry>
      <material name="dark"/>
    </visual>

    <collision>
      <origin xyz="0 0 0" rpy="0 0 0"/>
      <geometry>
        <sphere radius="0.0375" />
      </geometry>
    </collision>

    <inertial>
      <origin xyz="0 0 0" />
      <mass value="1.5" />
      <inertia ixx="8.4375e-04" ixy="0.0" ixz="0.0"
               iyy="8.4375e-04" iyz="0.0"
               izz="8.4375e-04" />
    </inertial>
  </link>

  <joint name="imu_joint" type="fixed">
    <parent link="base_link"/>
    <child link="imu_link"/>
    <origin xyz="0 0 0.175" rpy="0 0 0"/>
  </joint>

  <link name="imu_link"/>

  <joint name="scan_joint" type="fixed">
    <parent link="base_link"/>
    <child link="base_scan"/>
    <origin xyz="0.175 0 0.175" rpy="0 0 0"/>
  </joint>

  <link name="base_scan">
    <visual>
      <origin xyz="0 0 0.025" rpy="0 0 0"/>
      <geometry>
        <cylinder length="0.05" radius="0.025"/>
      </geometry>
      <material name="dark"/>
    </visual>

    <collision>
      <origin xyz="0 0 0.025" rpy="0 0 0"/>
      <geometry>
        <cylinder length="0.05" radius="0.025"/>
      </geometry>
    </collision>

    <inertial>
      <mass value="0.1" />
      <origin xyz="0 0 0.025" />
      <inertia ixx="0.0364583e-03" ixy="0.0" ixz="0.0"
               iyy="0.0364583e-03" iyz="0.0"
               izz="0.03125e-03" />
    </inertial>
  </link>

</robot>
